<?xml version="1.0"?>
<robot name="ur3e">
  <link name="ur3e_base_link">
    <visual>
      <geometry>
        <mesh filename="package://ur_e_description/meshes/ur3e/visual/base.dae" />
      </geometry>
      <material name="LightGrey">
        <color rgba="0.7 0.7 0.7 1.0" />
      </material>
    </visual>
    <collision>
      <geometry>
        <mesh filename="package://ur_e_description/meshes/ur3e/collision/base.stl" />
      </geometry>
    </collision>
    <inertial>
      <origin xyz="0.0 0.0 0.0" rpy="0 0 0" />
      <mass value="2.0" />
      <inertia ixx="0.0030531666666666667" ixy="0.0" ixz="0.0" iyy="0.0030531666666666667" iyz="0.0"
        izz="0.005625" />
    </inertial>
  </link>

  <joint name="ur3e_shoulder_pan_joint" type="revolute">
    <parent link="ur3e_base_link" />
    <child link="ur3e_shoulder_link" />
    <origin xyz="0.0 0.0 0.152" rpy="0.0 0.0 0.0" />
    <axis xyz="0 0 1" />
    <limit lower="-6.2831" upper="6.2831" effort="330.0" velocity="3.14" />
    <dynamics damping="0.0" friction="0.0" />
  </joint>

  <link name="ur3e_shoulder_link">
    <visual>
      <geometry>
        <mesh filename="package://ur_e_description/meshes/ur3e/visual/shoulder.dae" />
      </geometry>
      <material name="LightGrey">
        <color rgba="0.7 0.7 0.7 1.0" />
      </material>
    </visual>
    <collision>
      <geometry>
        <mesh filename="package://ur_e_description/meshes/ur3e/collision/shoulder.stl" />
      </geometry>
    </collision>
    <inertial>
      <origin xyz="0.0 0.0 0.0" rpy="0 0 0" />
      <mass value="2.0" />
      <inertia ixx="0.0030531666666666667" ixy="0.0" ixz="0.0" iyy="0.0030531666666666667" iyz="0.0"
        izz="0.005625" />
    </inertial>
  </link>

  <joint name="ur3e_shoulder_pan_joint" type="revolute">
    <parent link="ur3e_base_link" />
    <child link="ur3e_shoulder_link" />
    <origin xyz="0.0 0.0 0.152" rpy="0.0 0.0 0.0" />
    <axis xyz="0 0 1" />
    <limit lower="-6.2831" upper="6.2831" effort="330.0" velocity="3.14" />
    <dynamics damping="0.0" friction="0.0" />
  </joint>

  <link name="ur3e_shoulder_link">
    <visual>
      <geometry>
        <mesh filename="package://ur_e_description/meshes/ur3e/visual/shoulder.dae" />
      </geometry>
      <material name="LightGrey">
        <color rgba="0.7 0.7 0.7 1.0" />
      </material>
    </visual>
    <collision>
      <geometry>
        <mesh filename="package://ur_e_description/meshes/ur3e/collision/shoulder.stl" />
      </geometry>
    </collision>
    <inertial>
      <origin xyz="0.0 0.0 0.0" rpy="0 0 0" />
      <mass value="2.0" />
      <inertia ixx="0.008093166666666665" ixy="0.0" ixz="0.0" iyy="0.008093166666666665" iyz="0.0"
        izz="0.005625" />
    </inertial>
  </link>

  <joint name="ur3e_shoulder_lift_joint" type="revolute">
    <parent link="ur3e_shoulder_link" />
    <child link="ur3e_upper_arm_link" />
    <origin xyz="0.0 0.120 0.0" rpy="0.0 1.5707 0.0" />
    <axis xyz="0 1 0" />
    <limit lower="-6.2831" upper="6.2831" effort="330.0" velocity="3.14" />
    <dynamics damping="0.0" friction="0.0" />
  </joint>

  <link name="ur3e_upper_arm_link">
    <visual>
      <geometry>
        <mesh filename="package://ur_e_description/meshes/ur3e/visual/upperarm.dae" />
      </geometry>
      <material name="LightGrey">
        <color rgba="0.7 0.7 0.7 1.0" />
      </material>
    </visual>
    <collision>
      <geometry>
        <mesh filename="package://ur_e_description/meshes/ur3e/collision/upperarm.stl" />
      </geometry>
    </collision>
    <inertial>
      <origin xyz="0.0 0.0 0.122" rpy="0 0 0" />
      <mass value="3.42" />
      <inertia ixx="0.021777135" ixy="0.0" ixz="0.0" iyy="0.021777135" iyz="0.0"
        izz="0.009618749999999999" />
    </inertial>
  </link>

  <joint name="ur3e_elbow_joint" type="revolute">
    <parent link="ur3e_upper_arm_link" />
    <child link="ur3e_forearm_link" />
    <origin xyz="0.0 -0.093 0.244" rpy="0.0 0.0 0.0" />
    <axis xyz="0 1 0" />
    <limit lower="-3.14159" upper="3.14159" effort="150.0" velocity="3.14" />
    <dynamics damping="0.0" friction="0.0" />
  </joint>

  <link name="ur3e_forearm_link">
    <visual>
      <geometry>
        <mesh filename="package://ur_e_description/meshes/ur3e/visual/forearm.dae" />
      </geometry>
      <material name="LightGrey">
        <color rgba="0.7 0.7 0.7 1.0" />
      </material>
    </visual>
    <collision>
      <geometry>
        <mesh filename="package://ur_e_description/meshes/ur3e/collision/forearm.stl" />
      </geometry>
    </collision>
    <inertial>
      <origin xyz="0.0 0.0 0.1065" rpy="0 0 0" />
      <mass value="1.26" />
      <inertia ixx="0.00580944" ixy="0.0" ixz="0.0" iyy="0.00580944" iyz="0.0" izz="0.00315" />
    </inertial>
  </link>

  <joint name="ur3e_wrist_1_joint" type="revolute">
    <parent link="ur3e_forearm_link" />
    <child link="ur3e_wrist_1_link" />
    <origin xyz="0.0 0.0 0.213" rpy="0.0 1.5707 0.0" />
    <axis xyz="0 1 0" />
    <limit lower="-6.2831" upper="6.2831" effort="54.0" velocity="6.28" />
    <dynamics damping="0.0" friction="0.0" />
  </joint>

  <link name="ur3e_wrist_1_link">
    <visual>
      <geometry>
        <mesh filename="package://ur_e_description/meshes/ur3e/visual/wrist1.dae" />
      </geometry>
      <material name="LightGrey">
        <color rgba="0.7 0.7 0.7 1.0" />
      </material>
    </visual>
    <collision>
      <geometry>
        <mesh filename="package://ur_e_description/meshes/ur3e/collision/wrist1.stl" />
      </geometry>
    </collision>
    <inertial>
      <origin xyz="0.0 0.104 0.0" rpy="0 0 0" />
      <mass value="0.8" />
      <inertia ixx="0.0020849999999999996" ixy="0.0" ixz="0.0" iyy="0.0020849999999999996" iyz="0.0"
        izz="0.00225" />
    </inertial>
  </link>

  <joint name="ur3e_wrist_2_joint" type="revolute">
    <parent link="ur3e_wrist_1_link" />
    <child link="ur3e_wrist_2_link" />
    <origin xyz="0.0 0.104 0.0" rpy="0.0 0.0 0.0" />
    <axis xyz="0 0 1" />
    <limit lower="-6.2831" upper="6.2831" effort="54.0" velocity="6.28" />
    <dynamics damping="0.0" friction="0.0" />
  </joint>

  <link name="ur3e_wrist_2_link">
    <visual>
      <geometry>
        <mesh filename="package://ur_e_description/meshes/ur3e/visual/wrist2.dae" />
      </geometry>
      <material name="LightGrey">
        <color rgba="0.7 0.7 0.7 1.0" />
      </material>
    </visual>
    <collision>
      <geometry>
        <mesh filename="package://ur_e_description/meshes/ur3e/collision/wrist2.stl" />
      </geometry>
    </collision>
    <inertial>
      <origin xyz="0.0 0.0 0.085" rpy="0 0 0" />
      <mass value="0.8" />
      <inertia ixx="0.0020849999999999996" ixy="0.0" ixz="0.0" iyy="0.0020849999999999996" iyz="0.0"
        izz="0.00225" />
    </inertial>
  </link>

  <joint name="ur3e_wrist_3_joint" type="revolute">
    <parent link="ur3e_wrist_2_link" />
    <child link="ur3e_wrist_3_link" />
    <origin xyz="0.0 0.0 0.085" rpy="0.0 0.0 0.0" />
    <axis xyz="0 1 0" />
    <limit lower="-6.2831" upper="6.2831" effort="54.0" velocity="6.28" />
    <dynamics damping="0.0" friction="0.0" />
  </joint>

  <link name="ur3e_wrist_3_link">
    <visual>
      <geometry>
        <mesh filename="package://ur_e_description/meshes/ur3e/visual/wrist3.dae" />
      </geometry>
      <material name="LightGrey">
        <color rgba="0.7 0.7 0.7 1.0" />
      </material>
    </visual>
    <collision>
      <geometry>
        <mesh filename="package://ur_e_description/meshes/ur3e/collision/wrist3.stl" />
      </geometry>
    </collision>
    <inertial>
      <origin xyz="0.0 0.071 0.0" rpy="1.5707 0 0" />
      <mass value="0.35" />
      <inertia ixx="0.00014104999999999999" ixy="0.0" ixz="0.0" iyy="0.00014104999999999999"
        iyz="0.0" izz="0.0001792" />
    </inertial>
  </link>

  <joint name="ur3e_ee_fixed_joint" type="fixed">
    <parent link="ur3e_wrist_3_link" />
    <child link="robotiq_arg2f_base_link" />
    <origin xyz="0.0 0.092 0.0" rpy="0.0 1.5707 1.5707" />
  </joint>

  <link name="robotiq_arg2f_base_link">
    <inertial>
      <origin xyz="8.625E-08 -4.6583E-06 0.03145" rpy="0 0 0" />
      <mass value="0.22652" />
      <inertia ixx="0.00020005" ixy="-4.2442E-10" ixz="-2.9069E-10" iyy="0.00017832"
        iyz="-3.4402E-08" izz="0.00013478" />
    </inertial>
    <visual>
      <origin xyz="0 0 0" rpy="0 0 0" />
      <geometry>
        <mesh
          filename="package://robotiq/robotiq_2f_140_gripper_visualization/meshes/visual/robotiq_arg2f_base_link.stl" />
      </geometry>
      <material name="">
        <color rgba="0.1 0.1 0.1 1" />
      </material>
    </visual>
    <collision>
      <origin xyz="0 0 0" rpy="0 0 0" />
      <geometry>
        <mesh
          filename="package://robotiq/robotiq_2f_140_gripper_visualization/meshes/collision/robotiq_arg2f_base_link.stl" />
      </geometry>
    </collision>
  </link>

  <joint name="finger_joint" type="revolute">
    <origin xyz="0 -0.030601 0.054905" rpy="2.2957 0 0" />
    <parent link="robotiq_arg2f_base_link" />
    <child link="left_outer_knuckle" />
    <axis xyz="-1 0 0" />
    <limit lower="0" upper="0.7" velocity="2.0" effort="1000" />
  </joint>

  <link name="left_outer_knuckle">
    <inertial>
      <origin xyz="-0.000200000000003065 0.0199435877845359 0.0292245259211331" rpy="0 0 0" />
      <mass value="0.00853198276973456" />
      <inertia
        ixx="2.89328108496468E-06"
        ixy="-1.57935047237397E-19"
        ixz="-1.93980378593255E-19"
        iyy="1.86719750325683E-06"
        iyz="-1.21858577871576E-06"
        izz="1.21905238907251E-06" />
    </inertial>
    <visual>
      <origin xyz="0 0 0" rpy="0 0 0" />
      <geometry>
        <mesh
          filename="package://robotiq/robotiq_2f_140_gripper_visualization/meshes/visual/robotiq_arg2f_140_outer_knuckle.stl" />
      </geometry>
      <material name="">
        <color rgba="0.792156862745098 0.819607843137255 0.933333333333333 1" />
      </material>
    </visual>
    <collision>
      <origin xyz="0 0 0" rpy="0 0 0" />
      <geometry>
        <mesh
          filename="package://robotiq/robotiq_2f_140_gripper_visualization/meshes/collision/robotiq_arg2f_140_outer_knuckle.stl" />
      </geometry>
    </collision>
  </link>


  <joint name="right_outer_knuckle_joint" type="revolute">
    <origin xyz="0 0.030601 0.054905" rpy="2.2957 0 3.14159" />
    <parent link="robotiq_arg2f_base_link" />
    <child link="right_outer_knuckle" />
    <axis xyz="1 0 0" />
    <limit lower="-0.725" upper="0.725" velocity="2.0" effort="1000" />
    <mimic joint="finger_joint" multiplier="-1" offset="0" />
  </joint>

  <link name="right_outer_knuckle">
    <inertial>
      <origin xyz="-0.000200000000003065 0.0199435877845359 0.0292245259211331" rpy="0 0 0" />
      <mass value="0.00853198276973456" />
      <inertia
        ixx="2.89328108496468E-06"
        ixy="-1.57935047237397E-19"
        ixz="-1.93980378593255E-19"
        iyy="1.86719750325683E-06"
        iyz="-1.21858577871576E-06"
        izz="1.21905238907251E-06" />
    </inertial>
    <visual>
      <origin xyz="0 0 0" rpy="0 0 0" />
      <geometry>
        <mesh
          filename="package://robotiq/robotiq_2f_140_gripper_visualization/meshes/visual/robotiq_arg2f_140_outer_knuckle.stl" />
      </geometry>
      <material name="">
        <color rgba="0.792156862745098 0.819607843137255 0.933333333333333 1" />
      </material>
    </visual>
    <collision>
      <origin xyz="0 0 0" rpy="0 0 0" />
      <geometry>
        <mesh
          filename="package://robotiq/robotiq_2f_140_gripper_visualization/meshes/collision/robotiq_arg2f_140_outer_knuckle.stl" />
      </geometry>
    </collision>
  </link>

  <joint name="left_outer_finger_joint" type="fixed">
    <origin xyz="0 0.01821998610742 0.0260018192872234" rpy="0 0 0" />
    <parent link="left_outer_knuckle" />
    <child link="left_outer_finger" />
    <axis xyz="1 0 0" />
  </joint>

  <link name="left_outer_finger">
    <inertial>
      <origin xyz="0.00030115855001899 0.0373907951953854 -0.0208027427000385" rpy="0 0 0" />
      <mass value="0.022614240507152" />
      <inertia
        ixx="1.52518312458174E-05"
        ixy="9.76583423954399E-10"
        ixz="-5.43838577022588E-10"
        iyy="6.17694243867776E-06"
        iyz="6.78636130740228E-06"
        izz="1.16494917907219E-05" />
    </inertial>
    <visual>
      <origin xyz="0 0 0" rpy="0 0 0" />
      <geometry>
        <mesh
          filename="package://robotiq/robotiq_2f_140_gripper_visualization/meshes/visual/robotiq_arg2f_140_outer_finger.stl" />
      </geometry>
      <material name="">
        <color rgba="0.1 0.1 0.1 1" />
      </material>
    </visual>
    <collision>
      <origin xyz="0 0 0" rpy="0 0 0" />
      <geometry>
        <mesh
          filename="package://robotiq/robotiq_2f_140_gripper_visualization/meshes/collision/robotiq_arg2f_140_outer_finger.stl" />
      </geometry>
    </collision>
  </link>

  <joint name="right_outer_finger_joint" type="fixed">
    <origin xyz="0 0.01821998610742 0.0260018192872234" rpy="0 0 0" />
    <parent link="right_outer_knuckle" />
    <child link="right_outer_finger" />
    <axis xyz="1 0 0" />
  </joint>

  <link name="right_outer_finger">
    <inertial>
      <origin xyz="0.00030115855001899 0.0373907951953854 -0.0208027427000385" rpy="0 0 0" />
      <mass value="0.022614240507152" />
      <inertia
        ixx="1.52518312458174E-05"
        ixy="9.76583423954399E-10"
        ixz="-5.43838577022588E-10"
        iyy="6.17694243867776E-06"
        iyz="6.78636130740228E-06"
        izz="1.16494917907219E-05" />
    </inertial>
    <visual>
      <origin xyz="0 0 0" rpy="0 0 0" />
      <geometry>
        <mesh
          filename="package://robotiq/robotiq_2f_140_gripper_visualization/meshes/visual/robotiq_arg2f_140_outer_finger.stl" />
      </geometry>
      <material name="">
        <color rgba="0.1 0.1 0.1 1" />
      </material>
    </visual>
    <collision>
      <origin xyz="0 0 0" rpy="0 0 0" />
      <geometry>
        <mesh
          filename="package://robotiq/robotiq_2f_140_gripper_visualization/meshes/collision/robotiq_arg2f_140_outer_finger.stl" />
      </geometry>
    </collision>
  </link>

  <joint name="left_inner_knuckle_joint" type="revolute">
    <origin xyz="0 -0.0127 0.06142" rpy="2.2957 0 0" />
    <parent link="robotiq_arg2f_base_link" />
    <child link="left_inner_knuckle" />
    <axis xyz="1 0 0" />
    <limit lower="-0.8757" upper="0.8757" velocity="2.0" effort="1000" />
    <mimic joint="${prefix}finger_joint" multiplier="-1" offset="0" />
  </joint>


  <link name="left_inner_knuckle">
    <inertial>
      <origin xyz="0.000123011831763771 0.0507850843201817 0.00103968640075166" rpy="0 0 0" />
      <mass value="0.0271177346495152" />
      <inertia
        ixx="2.61910379223783E-05"
        ixy="-2.43616858946494E-07"
        ixz="-6.37789906117123E-09"
        iyy="2.8270243746167E-06"
        iyz="-5.37200748039765E-07"
        izz="2.83695868220296E-05" />
    </inertial>
    <visual>
      <origin xyz="0 0 0" rpy="0 0 0" />
      <geometry>
        <mesh
          filename="package://robotiq/robotiq_2f_140_gripper_visualization/meshes/visual/robotiq_arg2f_140_inner_knuckle.stl" />
      </geometry>
      <material name="">
        <color rgba="0.1 0.1 0.1 1" />
      </material>
    </visual>
    <collision>
      <origin xyz="0 0 0" rpy="0 0 0" />
      <geometry>
        <mesh
          filename="package://robotiq/robotiq_2f_140_gripper_visualization/meshes/collision/robotiq_arg2f_140_inner_knuckle.stl" />
      </geometry>
    </collision>
  </link>

  <joint name="right_inner_knuckle_joint" type="revolute">
    <origin xyz="0 0.0127 0.06142" rpy="2.29579 0 -3.14159" />
    <parent link="robotiq_arg2f_base_link" />
    <child link="right_inner_knuckle" />
    <axis xyz="1 0 0" />
    <limit lower="-0.8757" upper="0.8757" velocity="2.0" effort="1000" />
    <mimic joint="finger_joint" multiplier="-1" offset="0" />
  </joint>

  <link name="right_inner_knuckle">
    <inertial>
      <origin xyz="0.000123011831763771 0.0507850843201817 0.00103968640075166" rpy="0 0 0" />
      <mass value="0.0271177346495152" />
      <inertia
        ixx="2.61910379223783E-05"
        ixy="-2.43616858946494E-07"
        ixz="-6.37789906117123E-09"
        iyy="2.8270243746167E-06"
        iyz="-5.37200748039765E-07"
        izz="2.83695868220296E-05" />
    </inertial>
    <visual>
      <origin xyz="0 0 0" rpy="0 0 0" />
      <geometry>
        <mesh
          filename="package://robotiq/robotiq_2f_140_gripper_visualization/meshes/visual/robotiq_arg2f_140_inner_knuckle.stl" />
      </geometry>
      <material name="">
        <color rgba="0.1 0.1 0.1 1" />
      </material>
    </visual>
    <collision>
      <origin xyz="0 0 0" rpy="0 0 0" />
      <geometry>
        <mesh
          filename="package://robotiq/robotiq_2f_140_gripper_visualization/meshes/collision/robotiq_arg2f_140_inner_knuckle.stl" />
      </geometry>
    </collision>
  </link>

  <joint name="left_inner_finger_joint" type="revolute">
    <origin xyz="0 0.0817554015893473 -0.0282203446692936" rpy="-0.725 0 0" />
    <parent link="left_outer_finger" />
    <child link="left_inner_finger" />
    <axis xyz="1 0 0" />
    <limit lower="-0.8757" upper="0.8757" velocity="2.0" effort="1000" />
    <mimic joint="finger_joint" multiplier="1" offset="0" />
  </joint>

  <link name="left_inner_finger">
    <inertial>
      <origin xyz="0.000299999999999317 0.0160078233491243 -0.0136945669206257" rpy="0 0 0" />
      <mass value="0.0104003125914103" />
      <inertia
        ixx="2.71909453810972E-06"
        ixy="1.35402465472579E-21"
        ixz="-7.1817349065269E-22"
        iyy="7.69100314106116E-07"
        iyz="6.74715432769696E-07"
        izz="2.30315190420171E-06" />
    </inertial>
    <visual>
      <origin xyz="0 0 0" rpy="0 0 0" />
      <geometry>
        <mesh
          filename="package://robotiq/robotiq_2f_140_gripper_visualization/meshes/visual/robotiq_arg2f_140_inner_finger.stl" />
      </geometry>
      <material name="">
        <color rgba="0.1 0.1 0.1 1" />
      </material>
    </visual>
    <collision>
      <origin xyz="0 0 0" rpy="0 0 0" />
      <geometry>
        <mesh
          filename="package://robotiq/robotiq_2f_140_gripper_visualization/meshes/collision/robotiq_arg2f_140_inner_finger.stl" />
      </geometry>
    </collision>
  </link>

  <joint name="right_inner_finger_joint" type="revolute">
    <origin xyz="0 0.0817554015893473 -0.0282203446692936" rpy="-0.725 0 0" />
    <parent link="right_outer_finger" />
    <child link="right_inner_finger" />
    <axis xyz="1 0 0" />
    <limit lower="-0.8757" upper="0.8757" velocity="2.0" effort="1000" />
    <mimic joint="$finger_joint" multiplier="1" offset="0" />
  </joint>

  <link name="right_inner_finger">
    <inertial>
      <origin xyz="0.000299999999999317 0.0160078233491243 -0.0136945669206257" rpy="0 0 0" />
      <mass value="0.0104003125914103" />
      <inertia
        ixx="2.71909453810972E-06"
        ixy="1.35402465472579E-21"
        ixz="-7.1817349065269E-22"
        iyy="7.69100314106116E-07"
        iyz="6.74715432769696E-07"
        izz="2.30315190420171E-06" />
    </inertial>
    <visual>
      <origin xyz="0 0 0" rpy="0 0 0" />
      <geometry>
        <mesh
          filename="package://robotiq/robotiq_2f_140_gripper_visualization/meshes/visual/robotiq_arg2f_140_inner_finger.stl" />
      </geometry>
      <material name="">
        <color rgba="0.1 0.1 0.1 1" />
      </material>
    </visual>
    <collision>
      <origin xyz="0 0 0" rpy="0 0 0" />
      <geometry>
        <mesh
          filename="package://robotiq/robotiq_2f_140_gripper_visualization/meshes/collision/robotiq_arg2f_140_inner_finger.stl" />
      </geometry>
    </collision>
  </link>

  <joint name="left_inner_finger_pad_joint" type="fixed">
    <origin xyz="0 0.0457554015893473 -0.0272203446692936" rpy="0 0 0" />
    <parent link="left_inner_finger" />
    <child link="left_inner_finger_pad" />
    <axis xyz="0 0 1" />
  </joint>

  <link name="left_inner_finger_pad">
    <visual>
      <origin xyz="0 0 0" rpy="0 0 0" />
      <geometry>
        <box size="0.027 0.065 0.0075" />
      </geometry>
      <material name="">
        <color rgba="0.9 0.9 0.9 1" />
      </material>
    </visual>
    <collision>
      <origin xyz="0 0 0" rpy="0 0 0" />
      <geometry>
        <box size="0.03 0.07 0.0075" />
      </geometry>
      <material name="">
        <color rgba="0.9 0.0 0.0 1" />
      </material>
    </collision>
  </link>

  <joint name="right_inner_finger_pad_joint" type="fixed">
    <origin xyz="0 0.0457554015893473 -0.0272203446692936" rpy="0 0 0" />
    <parent link="right_inner_finger" />
    <child link="right_inner_finger_pad" />
    <axis xyz="0 0 1" />
  </joint>

  <link name="right_inner_finger_pad">
    <visual>
      <origin xyz="0 0 0" rpy="0 0 0" />
      <geometry>
        <box size="0.027 0.065 0.0075" />
      </geometry>
      <material name="">
        <color rgba="0.9 0.9 0.9 1" />
      </material>
    </visual>
    <collision>
      <origin xyz="0 0 0" rpy="0 0 0" />
      <geometry>
        <box size="0.03 0.07 0.0075" />
      </geometry>
      <material name="">
        <color rgba="0.9 0.0 0.0 1" />
      </material>
    </collision>
  </link>

</robot>