<?xml version="1.0"?>
<robot name="ur5e">


  <!-- <xacro:macro name="ur5e_robot" params="prefix joint_limited
    shoulder_pan_lower_limit:=${-pi}    shoulder_pan_upper_limit:=${pi}
    shoulder_lift_lower_limit:=${-pi}    shoulder_lift_upper_limit:=${pi}
    elbow_joint_lower_limit:=${-pi}    elbow_joint_upper_limit:=${pi}
    wrist_1_lower_limit:=${-pi}    wrist_1_upper_limit:=${pi}
    wrist_2_lower_limit:=${-pi}    wrist_2_upper_limit:=${pi}
    wrist_3_lower_limit:=${-pi}    wrist_3_upper_limit:=${pi}
    transmission_hw_interface:=hardware_interface/PositionJointInterface
    safety_limits:=false safety_pos_margin:=0.15
    safety_k_position:=20"> -->

    <property name="prefix" value="ur5"/>
    <!-- link lengths used in model -->
    <property name="upper_arm_length" value="0.425" />
    <property name="forearm_length" value="0.392" />
    <property name="wrist_1_length" value="0.127" />
    <property name="wrist_2_length" value="0.100" />
    <property name="wrist_3_length" value="0.100" />

    <link name="ur5e_base_link" >
      <visual>
        <geometry>
          <mesh filename="package://ur_e_description/meshes/ur5e/visual/base.dae" />
        </geometry>
        <material name="LightGrey">
          <color rgba="0.7 0.7 0.7 1.0"/>
        </material>
      </visual>
      <collision>
        <geometry>
          <mesh filename="package://ur_e_description/meshes/ur5e/collision/base.stl" />
        </geometry>
      </collision>
      <inertial>
        <origin xyz="0.0 0.0 0.0" rpy="0 0 0" />
        <mass value="4.0" />
        <inertia ixx="0.004433333333333333" ixy="0.0" ixz="0.0" iyy="0.004433333333333333" iyz="0.0" izz="0.0072"/>
      </inertial>
    </link>

    <joint name="ur5e_shoulder_pan_joint" type="revolute">
      <parent link="ur5e_base_link" />
      <child link = "ur5e_shoulder_link" />
      <origin xyz="0.0 0.0 0.163" rpy="0.0 0.0 0.0" />
      <axis xyz="0 0 1" />
      <limit lower="-6.2832" upper="6.2832" effort="150.0" velocity="3.14"/>
      <dynamics damping="0.0" friction="0.0"/>
    </joint>
   
    <link name="ur5e_shoulder_link">
      <visual>
        <geometry>
          <mesh filename="package://ur_e_description/meshes/ur5e/visual/shoulder.dae" />
        </geometry>
        <material name="LightGrey">
          <color rgba="0.7 0.7 0.7 1.0"/>
        </material>
      </visual>
      <collision>
        <geometry>
          <mesh filename="package://ur_e_description/meshes/ur5e/collision/shoulder.stl" />
        </geometry>
      </collision>
      <inertial>
        <origin xyz="0.0 0.0 0.0" rpy="0 0 0" />
        <mass value="3.7" />
        <inertia ixx="0.010267499999999999" ixy="0.0" ixz="0.0" iyy="0.010267499999999999" iyz="0.0" izz="0.00666"/>
      </inertial>
    </link>

    <joint name="ur5e_shoulder_lift_joint" type="revolute">
      <parent link="ur5e_shoulder_link" />
      <child link = "ur5e_upper_arm_link" />
      <origin xyz="0.0 0.138 0.0" rpy="0.0 1.5707 0.0" />
      <axis xyz="0 1 0" />
      <limit lower="-6.2831" upper="6.2831" effort="150.0" velocity="3.14"/>
      <dynamics damping="0.0" friction="0.0"/>
    </joint>

    <link name="ur5e_upper_arm_link">
      <visual>
        <geometry>
          <mesh filename="package://ur_e_description/meshes/ur5e/visual/upperarm.dae" />
        </geometry>
        <material name="LightGrey">
          <color rgba="0.7 0.7 0.7 1.0"/>
        </material>
      </visual>
      <collision>
        <geometry>
          <mesh filename="package://ur_e_description/meshes/ur5e/collision/upperarm.stl" />
        </geometry>
      </collision>
      <inertial>
        <origin xyz="0.0 0.0 0.2125" rpy="0 0 0" />
        <mass value="8.3930" />
        <inertia ixx="0.13388583541666665" ixy="0.0" ixz="0.0" iyy="0.13388583541666665" iyz="0.0" izz="0.0151074"/>
      </inertial>
    </link>

    <joint name="ur5e_elbow_joint" type="revolute">
      <parent link="ur5e_upper_arm_link" />
      <child link = "ur5e_forearm_link" />
      <origin xyz="0.0 -0.131 0.425" rpy="0.0 0.0 0.0" />
      <axis xyz="0 1 0" />
      <limit lower="-3.14159" upper="3.14159" effort="150.0" velocity="3.14"/>
      <dynamics damping="0.0" friction="0.0"/>
    </joint>

    <link name="ur5e_forearm_link">
      <visual>
        <geometry>
          <mesh filename="package://ur_e_description/meshes/ur5e/visual/forearm.dae" />
        </geometry>
        <material name="LightGrey">
          <color rgba="0.7 0.7 0.7 1.0"/>
        </material>
      </visual>
      <collision>
        <geometry>
          <mesh filename="package://ur_e_description/meshes/ur5e/collision/forearm.stl" />
        </geometry>
      </collision>
      <inertial>
        <origin xyz="0.0 0.0 0.196" rpy="0 0 0" />
        <mass value="2.2750" />
        <inertia ixx="0.03117963333333334" ixy="0.0" ixz="0.0" iyy="0.03117963333333334" iyz="0.0" izz="0.004095"/>
      </inertial>
    </link>

    <joint name="ur5e_wrist_1_joint" type="revolute">
      <parent link="ur5e_forearm_link" />
      <child link = "ur5e_wrist_1_link" />
      <origin xyz="0.0 0.0 ${forearm_length}" rpy="0.0 ${pi / 2.0} 0.0" />
      <axis xyz="0 1 0" />
      <limit lower="-6.2831" upper="6.2831" effort="28.0" velocity="6.28"/>
      <dynamics damping="0.0" friction="0.0"/>
    </joint>

    <link name="ur5e_wrist_1_link">
      <visual>
        <geometry>
          <mesh filename="package://ur_e_description/meshes/ur5e/visual/wrist1.dae" />
        </geometry>
        <material name="LightGrey">
          <color rgba="0.7 0.7 0.7 1.0"/>
        </material>
      </visual>
      <collision>
        <geometry>
          <mesh filename="package://ur_e_description/meshes/ur5e/collision/wrist1.stl" />
        </geometry>
      </collision>
      <inertial>
        <origin xyz="0.0 0.127 0.0" rpy="0 0 0" />
        <mass value="1.2190" />
        <inertia ixx="0.0025599000000000004" ixy="0.0" ixz="0.0" iyy="0.0025599000000000004" iyz="0.0" izz="0.0021942"/>
      </inertial>
    </link>

    <joint name="ur5e_wrist_2_joint" type="revolute">
      <parent link="ur5e_wrist_1_link" />
      <child link = "ur5e_wrist_2_link" />
      <origin xyz="0.0 ${wrist_1_length} 0.0" rpy="0.0 0.0 0.0" />
      <axis xyz="0 0 1" />
      <limit lower="-6.2831" upper="6.2831" effort="28.0" velocity="6.28"/>
      <dynamics damping="0.0" friction="0.0"/>
    </joint>

    <link name="ur5e_wrist_2_link">
      <visual>
        <geometry>
          <mesh filename="package://ur_e_description/meshes/ur5e/visual/wrist2.dae" />
        </geometry>
        <material name="LightGrey">
          <color rgba="0.7 0.7 0.7 1.0"/>
        </material>
      </visual>
      <collision>
        <geometry>
          <mesh filename="package://ur_e_description/meshes/ur5e/collision/wrist2.stl" />
        </geometry>
      </collision>
      <inertial>
        <origin xyz="0.0 0.0 0.100" rpy="0 0 0" />
        <mass value="1.2190" />
        <inertia ixx="0.0025599000000000004" ixy="0.0" ixz="0.0" iyy="0.0025599000000000004" iyz="0.0" izz="0.0021942"/>
      </inertial>
    </link>

    <joint name="ur5e_wrist_3_joint" type="revolute">
      <parent link="ur5e_wrist_2_link" />
      <child link = "ur5e_wrist_3_link" />
      <origin xyz="0.0 0.0 ${wrist_2_length}" rpy="0.0 0.0 0.0" />
      <axis xyz="0 1 0" />
      <limit lower="-6.2831" upper="6.2831" effort="28.0" velocity="6.28"/>
      <dynamics damping="0.0" friction="0.0"/>
    </joint>

    <link name="ur5e_wrist_3_link">
      <visual>
        <geometry>
          <mesh filename="package://ur_e_description/meshes/ur5e/visual/wrist3.dae" />
        </geometry>
        <material name="LightGrey">
          <color rgba="0.7 0.7 0.7 1.0"/>
        </material>
      </visual>
      <collision>
        <geometry>
          <mesh filename="package://ur_e_description/meshes/ur5e/collision/wrist3.stl" />
        </geometry>
      </collision>
      <inertial>
        <origin xyz="0.0 0.0771 0.0" rpy="1.5707 0 0" />
        <mass value="0.1879" />
        <inertia ixx="9.890414008333333e-05" ixy="0.0" ixz="0.0" iyy="9.890414008333333e-05" iyz="0.0" izz="0.0001321171875"/>
      </inertial>
    </link>

    <!--
    <joint name="ur5e_ee_fixed_joint" type="fixed">
      <parent link="ur5e_wrist_3_link" />
      <child link = "ur5e_ee_link" />
      <origin xyz="0.0 ${wrist_3_length} 0.0" rpy="0.0 0.0 ${pi/2.0}" />
    </joint>

    <link name="ur5e_ee_link">
      <collision>
        <geometry>
          <box size="0.01 0.01 0.01"/>
        </geometry>
        <origin rpy="0 0 0" xyz="-0.01 0 0"/>
      </collision>
    </link>

    <xacro:ur_arm_transmission prefix="ur5e_" />
    <xacro:ur_arm_gazebo prefix="ur5e_" />

    <!-- ROS base_link to UR 'Base' Coordinates transform -->
    <link name="ur5e_base"/>
    <joint name="ur5e_base_link-base_fixed_joint" type="fixed">
      <!-- NOTE: this rotation is only needed as long as base_link itself is
                 not corrected wrt the real robot (ie: rotated over 180
                 degrees)
      -->
      <origin xyz="0 0 0" rpy="0 0 ${-pi}"/>
      <parent link="ur5e_base_link"/>
      <child link="ur5e_base"/>
    </joint>

    <!-- Frame coincident with all-zeros TCP on UR controller -->
    <link name="ur5e_tool0"/>
    <joint name="ur5e_wrist_3_link-tool0_fixed_joint" type="fixed">
      <origin xyz="0 ${wrist_3_length} 0" rpy="${pi/-2.0} 0 0"/>
      <parent link="ur5e_wrist_3_link"/>
      <child link="ur5e_tool0"/>
    </joint> -->
</robot>
